# 11_1 테스트 작성하는 방법

테스트 코드는 테스트 코드가 아닌 코드가 예상한 대로 동작하는 것을 검증하는
코드입니다.

1. 필요한 데이터나 state를 설정합니다.
2. 테스트하고자 하는 코드를 실행합니다.
3. 당신이 예상한 결과를 assert합니다.

러스트가 테스트를 위해 제공하는 기능들을 살펴보겠습니다. `test` attribute와, 몇
가지 macro, 그리고 `should_panic` attribute입니다.

## 11_1_1 The Anatony of a Test function

가장 간단하게 말하면, 테스트는 `test` attribute로 annotate된 함수입니다.
Attribute는 러스트 코드 조각들의 메타데이터인데, 예를 들면 Struct의 `derive`
attribute가 있습니다.

테스트 함수를 만들려면, `fn` line 직전에 `#[test]`를 써주면 됩니다.
그 다음 `cargo test`를 호출해서 테스트 러너 바이너리가 만들어지게 하여 테스트로
마킹된 함수들을 실행하고 각 테스트 함수가 성공했는지 실패했는지 보고합니다.

Cargo로 library project를 새로 만들 때마다, test 함수가 동봉된 테스트 모듈이
자동적으로 생성됩니다. 이 테스트 모듈은 테스트 작성을 위한 템플릿을 제공하므로
당신이 새 프로젝트를 생성할 때마다 정확한 구조와 문법을 찾아볼 필요는 없습니다.
당신이 원하는 만큼 테스트 함수 및 테스트 모듈을 추가할 수 있습니다.

Ex) Adder

```rust
$ cargo new adder --lib
     Created library `adder` project
$ cd adder
```

```rust
// src/lib.rs
#[cfg(test)]
mod tests {
    #[test]
    fn it_works() {
        let result = 2 + 2;
        assert_eq!(result, 4);
    }
}
```

`#[test]` attribute는 테스트임을 표시해주며, test runner는 이를 테스트로
인식하게 됩니다. 이것이 중요한 이유는, 우리가 `tests` 모듈에 테스트가 아닌
함수를 넣어서 common scenario나 common operation을 반복해서 하도록 도울 수 있기
때문입니다. 따라서 테스트는 항상 `#[test]` attribute가 붙어있어야 합니다.

```bash
# Test result
$ cargo test
   Compiling adder v0.1.0 (file:///projects/adder)
    Finished test [unoptimized + debuginfo] target(s) in 0.57s
     Running unittests src/lib.rs (target/debug/deps/adder-92948b65e88960b4)

running 1 test
test tests::it_works ... ok

test result: ok. 1 passed; 0 failed; 0 ignored; 0 measured; 0 filtered out; finished in 0.00s

   Doc-tests adder

running 0 tests

test result: ok. 0 passed; 0 failed; 0 ignored; 0 measured; 0 filtered out; finished in 0.00s

```
Cargo가 compile에 성공하고 테스트를 돌렸습니다. `it_works`를 호출해서 ok가
반환되었음을 확인할 수 있습니다.

- 때로는, 테스트를 ignore하겠다는 마킹을 하여 특정 instance에서는 안 돌게 할 수
    있습니다. 이 챕터 안의 "Ignoring Some Tests Unless Specifically Requested"
    파트에서 다룹니다. 이 짓을 하지 않았기 때문에 `0 ignored` message가 뜨는
    것입니다.
- 또한 Rust에게 argument를 건네서 해당 argument가 패턴 매칭되는 테스트만 돌릴
    수도 있습니다. 이를 _filtering_이라고 부르며 "Running a Subset of Tests by
    Name" 파트에서 다룹니다. 이런 필터가 적용되지 않았으므로 `0 filtered out`이
    나왔습니다.
- `0 measured` 통계는 퍼포먼스를 측정하는 벤치마크를 위함입니다. 다만 현재는
    Rust nightly 버전에서만 지원합니다. 문서를 보고 벤치마크 테스트를
    확인해보세요.
- Doc-tests adder 파트는 documentation에 대한 테스트 결과를 다룹니다. 지금은
    documentation test를 하나도 가지지 않고 있지만, 러스트는 우리의 API
    documentation에 나타난 어떤 코드 예시라도 컴파일할 수 있습니다. 이를 통해
    문서와 코드가 동기화되도록 돕습니다. Ch 14에 있는 "Documentation Comments as
    Tests"에서 다룹니다.

이제 테스트를 커스터마이즈해봅시다. 예를 들어 테스트 함수 `it_works`의 이름을
바꿀 수 있습니다. 혹은 실패하는 테스트를 만들 수도 있습니다.

```rust
#[cfg(test)]
mod tests {
    #[test]
    fn exploration() {
        assert_eq!(2 + 2, 4);
    }

    #[test]
    fn another() {
        panic!("Make this test fail");
    }
}
```

1 passed, 1 failed 메세지가 나옵니다. 또한 테스트에서 panicked라고 알려줍니다.

또한 테스트 결과 맨 아래쪽에 failures: 실패한 테스트 이름들 섹션이 따로
정리되어서 나옵니다. 이는 우리가 디버깅할 때 함수 이름만 간략하게 모아서 보기
좋게 만들어줍니다. Ch 11.2 controlling how tests are run 파트에서 더 자세히
배웁니다.

이제 다른 테스트들을 배웁니다. `panic!`보다 유용한 매크로를 배우게 됩니다.

## 11_1_2 `assert!` macro로 결과 확인하기

`assert!` 매크로는 standard library에 의해 주어지며, 특정 컨디션이 true임을
확실하게 만들 때 사용합니다.
`assert!` 매크로는 argument를 1개 받는데, boolean을 받습니다. 이게 true면 아무
일도 일어나지 않습니다. 하지만 false면 `panic!`이 일어나서 테스트가 실패합니다.

```rust
#[derive(Debug)]
struct Rectangle {
    width: u32,
    height: u32,
}

impl Rectangle {
    fn can_hold(&self, other: &Rectangle) -> bool {
        self.width > other.width && self.height > other.height
    }
}

#[cfg(test)]
mod tests {
    use super::*;

    #[test]
    fn larger_can_hold_smaller() {
        let larger = Rectangle {
            width: 8,
            height: 7,
        };
        let smaller = Rectangle {
            width: 5,
            height: 1,
        };

        assert!(larger.can_hold(&smaller));
    }
    
    #[test]
    fn smaller_cannot_hold_larger() {
        let larger = Rectangle {
            width: 8,
            height: 7,
        };
        let smaller = Rectangle {
            width: 5,
            height: 1,
        };

        assert!(!smaller.can_hold(&larger));
    }
}
```

NOTE: `use super::*;`를 추가했습니다. Test 모듈 역시 일반적인 모듈이므로
visibility rule 역시 그대로 따릅니다. `tests`가 inner module이므로, `Rectangle`
등의 외부의 struct를 사용하려면 `use super::*;`로 가져와야 합니다.

`can_hold`의 구현이 이상해지면 테스트가 실패합니다.

```rust
// --snip--
impl Rectangle {
    fn can_hold(&self, other: &Rectangle) -> bool {
        self.width < other.width && self.height > other.height
    }
}
```

## 11_1_3 `assert_eq!`와 `assert_ne!`로 Equality 확인하기

물론 같다, 다르다를 판단할 때 `==` operator를 `assert!`와 같이 사용할 수
있습니다.
그러나 같은 것을 테스트하는 것은 굉장히 흔한 일이기 때문에 `assert_eq!` 과
`assert_ne!`를 따로 가지고 있습니다. 각 매크로는 generic 타입 2개를 가지며,
`assert_eq!`의 경우 두 값의 타입이 같고 실제 값도 같아야 합니다.

```rust
pub fn add_two(a: i32) -> i32 {
    a + 2
}

#[cfg(test)]
mod tests {
    use super::*;

    #[test]
    fn it_adds_two() {
        assert_eq!(4, add_two(2));
    }
}
```

테스트를 실패시키려면 예를 들어 아래와 같은 잘못된 로직을 줄 수 있습니다.

```rust
pub fn add_two(a: i32) -> i32 {
    a + 3
}
```

```console
$ cargo test
   Compiling adder v0.1.0 (file:///projects/adder)
    Finished test [unoptimized + debuginfo] target(s) in 0.61s
     Running unittests src/lib.rs (target/debug/deps/adder-92948b65e88960b4)

running 1 test
test tests::it_adds_two ... FAILED

failures:

---- tests::it_adds_two stdout ----
thread 'tests::it_adds_two' panicked at 'assertion failed: `(left == right)`
  left: `4`,
 right: `5`', src/lib.rs:11:9
note: run with `RUST_BACKTRACE=1` environment variable to display a backtrace


failures:
    tests::it_adds_two

test result: FAILED. 0 passed; 1 failed; 0 ignored; 0 measured; 0 filtered out; finished in 0.00s

error: test failed, to rerun pass `--lib`
```

에러 메세지를 보면 메세지가 더 자세해진 것을 알 수 있습니다. 왼쪽 값, 오른쪽
값을 같다고 가정하는 assertion이 실패했으며, 각 값이 어떤 것이었는지까지
알려줍니다.

참고로, 특정 언어나 테스트 프레임워크에서는 왼쪽이 `expected`, 오른쪽이
`actual`인 경우가 있습니다. 그래서 argument를 배치하는 순서가 영향을 줍니다.
그러나 rust에서는 그냥 left, right라고 하므로, 어떤 순서로 주든지 상관없습니다.

`assert_ne!`는 특히 이런 상황에 유용합니다 - 이 값이 어떤 값이 될지는 모르지만
적어도 "이 값만큼은 되면 안 된다"는 걸 확실하게 알고 있을 때. 예를 들어 input을
반드시 어떤 식으로든 변환하는 함수가 있다고 가정하면, assert_ne!(expected,
input) 을 작성해서 같지 않다는 assertion을 할 수 있죠.

사실 수면 아래에서 `assert_ne!, assert_eq!`은 `!=, ==`를 사용합니다. Assertion에
실패하면 해당 argument들을 debug formatting으로 출력하므로, 해당 값들이 반드시
`PPartialEq`, `Debug` trait을 구현해야 한다는 뜻입니다.
다행히도 모든 primitive 타입과 대부분의 standard library들은 이것들을
구현해두었습니다. 만약 struct, enum을 정의해서 해당 타입들에 assert_eq,
assert_ne를 쓰려 한다면, `PartialEq`를 구현하고 또한 `Debug`를 구현해야 합니다.
이 두 가지 trait들은 모두 derivable하므로, Struct, Enum definition의
annotation으로 `#[derive(PartialEq, Debug)]`를 추가하면 됩니다.

## 11_1_4 커스텀 실패 메세지
매크로와 함께 failure message를 optional argument로 제공해서 커스텀 에러
메세지를 출력할 수 있습니다.

필요한 argument 뒤에 오는 모든 argument들은 `format!` 매크로의 형식대로
들어옵니다. . 따라서 먼저 format string을 넣고, 그 뒤에 `{}`들을 채우는 값들을
전달해주면 됩니다.
커스텀 메세지는 assertion이 뜻하는 바를 문서로 적을 때 유용합니다.

```rust
pub fn greeting(name: &str) -> String {
    format!("Hello {}!", name)
}

#[cfg(test)]
mod tests {
    use super::*;

    #[test]
    fn greeting_contains_name() { // 좋지 않은 assert
        let result = greeting("Carol");
        assert!(result.contains("Carol"));
    }

    #[test]
    fn greeting_contains_name() { // 좋은 assert
        let result = greeting("Carol");
        assert!(
            result.contains("Carol"),
            "Greeting did not contain name, value was `{}`",
            result
        );
    }
}
```

## 11_1_4 Panic을 `should_panic`으로 검사하기

반환되는 값을 확인하는 것에 더해, 우리의 코드가 우리가 원하던 대로 에러 상황을
잘 관리하는지 확인하는 것도 중요합니다. 예를 들어 `Guess` type (Ch 9)를
생각해보면, 다른 코드들은 `Guess` instance가 1~100 사이의 값만을 들고 있다고
가정한 상태에서 의존하고 있습니다. 이를 확실하게 만들어주는 테스트를, 범위 밖의
값이 들어왔을 때 panic을 일으키는 것으로 작성하여 진행할 수 있습니다.

이를 위해 `#[should_panic]` annotation을 추가합니다. 이 annotation이 붙은
테스트는 panic할 때만 성공하고, panic하지 않으면 실패합니다.

```rust
pub struct Guess {
    value: i32,
}

impl Guess {
    pub fn new(value: i32) -> Guess {
        if value < 1 || value > 100 {
            panic!("Guess value must be between 1 and 100, got {}.", value);
        }

        Guess { value }
    }
}

#[cfg(test)]
mod tests {
    use super::*;

    #[test]
    #[should_panic]
    fn greater_than_100() {
        Guess::new(200);
    }
}
```

```shell
$ cargo test
   Compiling guessing_game v0.1.0 (file:///projects/guessing_game)
    Finished test [unoptimized + debuginfo] target(s) in 0.58s
     Running unittests src/lib.rs (target/debug/deps/guessing_game-57d70c3acb738f4d)

running 1 test
test tests::greater_than_100 - should panic ... ok

test result: ok. 1 passed; 0 failed; 0 ignored; 0 measured; 0 filtered out; finished in 0.00s

   Doc-tests guessing_game

running 0 tests

test result: ok. 0 passed; 0 failed; 0 ignored; 0 measured; 0 filtered out; finished in 0.00s

```

만약 아래와 같은 버그가 코드에 있다면:

```rust
// --snip--
impl Guess {
    pub fn new(value: i32) -> Guess {
        if value < 1 { // 이러면 100보다 큰 값이 들어와도 panic하지 않습니다.
            panic!("Guess value must be between 1 and 100, got {}.", value);
        }

        Guess { value }
    }
}
```

테스트가 실패합니다.

```shell
$ cargo test
   Compiling guessing_game v0.1.0 (file:///projects/guessing_game)
    Finished test [unoptimized + debuginfo] target(s) in 0.62s
     Running unittests src/lib.rs (target/debug/deps/guessing_game-57d70c3acb738f4d)

running 1 test
test tests::greater_than_100 - should panic ... FAILED

failures:

---- tests::greater_than_100 stdout ----
note: test did not panic as expected

failures:
    tests::greater_than_100

test result: FAILED. 0 passed; 1 failed; 0 ignored; 0 measured; 0 filtered out; finished in 0.00s

error: test failed, to rerun pass `--lib`
```

그러나 테스트 실패 메세지가 그다지 도움이 안 되는 것을 확인할 수 있습니다. 이를
위해 `should_panic` 뒤에 커스텀 에러 메세지를 `expected` 파라미터로 줄 수
있습니다. 이 에러 메세지가 panic! 메세지의 substring으로 존재하면 테스트에
성공하고, 아니면 테스트에 실패합니다.

```rust
// --snip--

impl Guess {
    pub fn new(value: i32) -> Guess {
        if value < 1 {
            panic!(
                "Guess value must be greater than or equal to 1, got {}.",
                value
            );
        } else if value > 100 {
            panic!(
                "Guess value must be less than or equal to 100, got {}.",
                value
            );
        }

        Guess { value }
    }
}

#[cfg(test)]
mod tests {
    use super::*;

    #[test]
    #[should_panic(expected = "less than or equal to 100")]
    fn greater_than_100() {
        Guess::new(200);
    }
}
```

만약 다음과 같이 서순을 일으키면, 에러가 발생합니다.

```rust
        if value < 1 {
            panic!(
                "Guess value must be less than or equal to 100, got {}.",
                value
            );
        } else if value > 100 {
            panic!(
                "Guess value must be greater than or equal to 1, got {}.",
                value
            );
        }
```

```shell
$ cargo test
   Compiling guessing_game v0.1.0 (file:///projects/guessing_game)
    Finished test [unoptimized + debuginfo] target(s) in 0.66s
     Running unittests src/lib.rs (target/debug/deps/guessing_game-57d70c3acb738f4d)

running 1 test
test tests::greater_than_100 - should panic ... FAILED

failures:

---- tests::greater_than_100 stdout ----
thread 'tests::greater_than_100' panicked at 'Guess value must be greater than or equal to 1, got 200.', src/lib.rs:13:13
note: run with `RUST_BACKTRACE=1` environment variable to display a backtrace
note: panic did not contain expected string
      panic message: `"Guess value must be greater than or equal to 1, got 200."`,
 expected substring: `"less than or equal to 100"`

failures:
    tests::greater_than_100

test result: FAILED. 0 passed; 1 failed; 0 ignored; 0 measured; 0 filtered out; finished in 0.00s

error: test failed, to rerun pass `--lib`
```

## 11_1_5 `Result<T, E>`를 테스트에 쓰기

지금까지 실패하면 panic하는 테스트만 살펴봤습니다. 이를 `Result<T, E>`와도 쓸 수
있습니다.

```rust
#[cfg(test)]
mod tests {
    #[test]
    fn it_works() -> Result<(), String> {
        if 2 + 2 == 4 {
            Ok(())
        } else {
            Err(String::from("two plus two does not equal four"))
        }
    }
}
```

`it_works`는 `Result<(), String>` 타입을 반환합니다. 따라서 함수 body에서
`assert_eq!`을 부르는 대신 테스트가 성공할 때 `Ok(())`를 반환하고, 실패할 때
`Err(String::from("..."))`를 반환합니다.

따라서 이 경우 `#[should_panic]` annotation을 쓸 수 없습니다. 또한 이
operation이 `Err`를 반환하는 것을 assert하려면, `?` operator를 _쓰지 마세요_.
대신, `assert!(value.is_err())`로 써야 합니다.
